Workbook

Sheet LEIA-ME
A1: alternafit - planilha v4 (modelo de banco de dados)
A3: Cada aba é uma TABELA do banco. A primeira linha é o nome das colunas (snake_case, sem acento) e cada linha seguinte é um registro.
A4: Os IDs são números fixos (não fórmulas): podem ser importados direto no MySQL/Django. Nunca reordene ou renumere IDs sem atualizar as tabelas que os usam.
A5: Colunas cinza (começam com _aux_ ou _calc_) são só para leitura humana/validação: NÃO importar no banco.
A7: TABELAS
A8: Cadastros (lookup): nivel_dificuldade, grupo_muscular, equipamento, padrao_movimento, fonte
A9: Principal: exercicio (1 linha por exercício, nome único em português; termo em inglês em nome_en)
A10: Relacionamentos N-N: exercicio_grupo_muscular, exercicio_equipamento, exercicio_alternativo, exercicio_fonte
A11: Detalhes: exercicio_passo (passo a passo), exercicio_apelido (nomes alternativos para a busca)
A12: Conferência: checagem_regras (confere automaticamente a regra de 2 a 4 alternativas com 1 sem equipamento) e mudancas
A14: REGRAS DO MODELO
A15: 1. Nenhum exercício aparece duas vezes. Variações reais (ex.: Encolhimento com Halteres x com Barra) são exercícios distintos; tradução do mesmo exercício vira apelido.
... A26: Coluna status_dados (aba exercicio): 'Com fonte' = confirmado em fonte técnica (ver exercicio_fonte); 'Sem fonte - dado do Lucas' e 'Sem fonte específica (revisar)' = precisam de validação.

Sheet exercicio
A1: id | B1: nome | C1: nome_en | D1: descricao | E1: nivel_id | F1: padrao_movimento_id | G1: dica_execucao | H1: video_url | I1: status_dados | J1: observacao | K1: _calc_exige_equipamento | L1: _calc_n_alternativas
A2: 1 | B2: Supino Reto com Barra | C2: Barbell Bench Press | D2: Pressão horizontal com barra, deitado em banco reto, principal exercício composto de peitoral | E2: 2 | F2: 1 | G2: Mantenha os cotovelos a cerca de 45-75° do tronco na descida (não a 90°); não trave o cotovelo no topo do movimento | I2: Com fonte | K2: =COUNTIF(exercicio_equipamento!$A$2:$A$400,A2)>0 -> TRUE | L2: =COUNTIF(exercicio_alternativo!$A$2:$A$400,A2) -> 4
A3: 2 | B3: Supino Inclinado com Halteres | C3: Incline Dumbbell Press | D3: Pressão em banco inclinado (30°), enfatiza a porção clavicular (superior) do peitoral maior | E3: 2 | F3: 1 | G3: Não trave os cotovelos no topo; não deixe os halteres caírem rápido nem 'quicar' no fundo do movimento | H3: https://www.youtube.com/watch?v=F4Q1g2z8MWM | I3: Com fonte | K3: =COUNTIF(exercicio_equipamento!$A$2:$A$400,A3)>0 -> TRUE | L3: =COUNTIF(exercicio_alternativo!$A$2:$A$400,A3) -> 4
A4: 3 | B4: Voador Peitoral | C4: Pec Deck Fly | D4: Movimento de adução horizontal dos braços na máquina peck deck, isola o peitoral com trajetória guiada | E4: 1 | F4: 3 | G4: Ajuste banco e manoplas para apoiar os cotovelos com os braços na horizontal; mantenha leve flexão fixa nos cotovelos e controle a volta | H4: https://www.youtube.com/watch?v=QRehkbV0R48 | I4: Com fonte | K4: =COUNTIF(exercicio_equipamento!$A$2:$A$400,A4)>0 -> TRUE | L4: =COUNTIF(exercicio_alternativo!$A$2:$A$400,A4) -> 3
A5: 4 | B5: Flexão de Braço | C5: Push-up | D5: Empurra o corpo do chão com os braços, mantendo o corpo alinhado da cabeça aos pés | E5: 2 | F5: 1 | G5: Contraia o abdômen para manter o tronco firme e o corpo em linha reta da cabeça aos pés; mãos na largura dos ombros, pense em empurrar o chão | I5: Com fonte | J5: Nível 2 conforme ACE (Intermediário). Versão mais fácil: flexão com as mãos apoiadas na parede | K5: =COUNTIF(exercicio_equipamento!$A$2:$A$400,A5)>0 -> FALSE | L5: =COUNTIF(exercicio_alternativo!$A$2:$A$400,A5) -> 4
A6: 5 | B6: Flexão com Apoio Afastado | C6: Wide Push-up | D6: Flexão com as mãos mais afastadas que os ombros, maior ênfase no peitoral | E6: 1 | F6: 1 | G6: Mãos mais afastadas que os ombros, desça flexionando os cotovelos para os lados até o peito ficar logo abaixo da linha dos cotovelos | I6: Com fonte | K6: =COUNTIF(exercicio_equipamento!$A$2:$A$400,A6)>0 -> FALSE | L6: =COUNTIF(exercicio_alternativo!$A$2:$A$400,A6) -> 4
A7: 6 | B7: Flexão com Pés Elevados | C7: Decline Push-up | D7: Flexão com os pés apoiados em um ponto mais alto (parede), enfatiza a parte superior do peitoral e os ombros | E7: 2 | F7: 1 | G7: Mãos um pouco mais largas que os ombros, corpo reto da cabeça aos pés; quanto mais alto o apoio dos pés, maior a ênfase na parte superior do peitoral/deltoide anterior | I7: Com fonte | J7: Pés apoiados na parede (parede não conta como equipamento) | K7: =COUNTIF(exercicio_equipamento!$A$2:$A$400,A7)>0 -> FALSE | L7: =COUNTIF(exercicio_alternativo!$A$2:$A$400,A7) -> 4
A8: 7 | B8: Mergulho em Paralelas | C8: Parallel Bar Dip | D8: Desce e sobe o corpo apoiado em barras paralelas, flexionando e estendendo os cotovelos | E8: 2 | F8: 2 | G8: Segure as barras na largura dos ombros; desça controlando até os braços ficarem paralelos ao chão (mais fundo só se não houver dor) e suba estendendo os cotovelos | I8: Com fonte | K8: =COUNTIF(exercicio_equipamento!$A$2:$A$400,A8)>0 -> TRUE | L8: =COUNTIF(exercicio_alternativo!$A$2:$A$400,A8) -> 3
A9: 8 | B9: Flexão Diamante | C9: Diamond Push-up | D9: Flexão com as mãos juntas formando um diamante sob o peito, maior ênfase no tríceps | E9: 2 | F9: 1 | G9: Mãos juntas sob o peito formando um diamante, cotovelos colados ao tronco, descer até quase tocar o peito no chão | I9: Com fonte | K9: =COUNTIF(exercicio_equipamento!$A$2:$A$400,A9)>0 -> FALSE | L9: =COUNTIF(exercicio_alternativo!$A$2:$A$400,A9) -> 4
A10: 9 | B10: Flexão em Pique | C10: Pike Push-up | D10: Flexão com o quadril elevado em V invertido; simula o desenvolvimento de ombros | E10: 2 | F10: 2 | G10: Posição de V invertido, cotovelos a ~45° do corpo, desça a cabeça em direção ao chão sem deixar o quadril cair | I10: Com fonte | K10: =COUNTIF(exercicio_equipamento!$A$2:$A$400,A10)>0 -> FALSE | L10: =COUNTIF(exercicio_alternativo!$A$2:$A$400,A10) -> 4
A11: 10 | B11: Flexão nas Pontas dos Dedos | C11: Fingertip Push-up | D11: Flexão apoiada apenas nas pontas dos dedos; exige grande força de preensão (começar com joelhos no chão) | E11: 3 | F11: 1 | G11: Flexão de braço apoiada apenas nas pontas dos dedos; exige grande força de preensão. Fazer primeiro com os joelhos no chão | I11: Com fonte | K11: =COUNTIF(exercicio_equipamento!$A$2:$A$400,A11)>0 -> FALSE | L11: =COUNTIF(exercicio_alternativo!$A$2:$A$400,A11) -> 3
A12: 11 | B12: Desenvolvimento com Halteres | C12: Dumbbell Shoulder Press | D12: Pressão vertical dos halteres acima da cabeça, sentado ou em pé, principal exercício composto de deltoide anterior | E12: 2 | F12: 2 | G12: Mantenha o core contraído para estabilizar o tronco; evite hiperextensão lombar; desça os halteres de forma controlada até a altura dos ombros | H12: https://www.youtube.com/watch?v=eufDL9MmF8A | I12: Com fonte | J12: Nível revisado de 3 para 2 na pesquisa - confirmar com professor | K12: =COUNTIF(exercicio_equipamento!$A$2:$A$400,A12)>0 -> TRUE | L12: =COUNTIF(exercicio_alternativo!$A$2:$A$400,A12) -> 3
A13: 12 | B13: Elevação Lateral no Cabo | C13: Cable Lateral Raise | D13: Elevação do braço lateralmente contra a resistência de um cabo/polia baixa, isola a porção lateral do deltoide | E13: 2 | F13: 3 | G13: Fique de pé próximo à polia; eleve a alça lateralmente e com controle até o braço ficar na horizontal; priorize execução estrita com carga leve | H13: https://www.youtube.com/watch?v=9zh-c9JQN9k | I13: Com fonte | K13: =COUNTIF(exercicio_equipamento!$A$2:$A$400,A13)>0 -> TRUE | L13: =COUNTIF(exercicio_alternativo!$A$2:$A$400,A13) -> 3
A14: 13 | B14: Elevação Lateral na Máquina | C14: Machine Lateral Raise | D14: Elevação lateral dos braços em máquina guiada; isola o deltoide lateral | E14: 1 | F14: 3 | G14: Ajuste o banco para alinhar os ombros ao eixo da máquina; eleve os braços até a altura dos ombros sem encolher o trapézio | I14: Com fonte | K14: =COUNTIF(exercicio_equipamento!$A$2:$A$400,A14)>0 -> TRUE | L14: =COUNTIF(exercicio_alternativo!$A$2:$A$400,A14) -> 3
A15: 14 | B15: Crucifixo Invertido na Polia | C15: Cable Reverse Fly | D15: Abertura horizontal dos braços contra a resistência de duas polias cruzadas, isola a porção posterior do deltoide | E15: 1 | F15: 3 | G15: Posicione duas polias na altura dos ombros; segure a alça oposta com cada mão; abra os braços até a altura dos ombros, pausando antes de retornar devagar | H15: https://www.youtube.com/watch?v=vVDeOaw1T5g | I15: Com fonte | K15: =COUNTIF(exercicio_equipamento!$A$2:$A$400,A15)>0 -> TRUE | L15: =COUNTIF(exercicio_alternativo!$A$2:$A$400,A15) -> 3
A16: 15 | B16: Elevação Prona em T | C16: Prone T-Raise | D16: Deitado de bruços, eleva os braços abertos em T; trabalha deltoide posterior e escápulas | E16: 1 | F16: 3 | G16: Deite de bruços, braços abertos em T com palmas para baixo; eleve os braços poucos centímetros do chão, segure e desça devagar | I16: Com fonte | K16: =COUNTIF(exercicio_equipamento!$A$2:$A$400,A16)>0 -> FALSE | L16: =COUNTIF(exercicio_alternativo!$A$2:$A$400,A16) -> 3
A17: 16 | B17: Anjo da Neve Invertido | C17: Reverse Snow Angel | D17: Deitado de bruços, move os braços em arco como um anjo na neve ao contrário | E17: 1 | F17: 3 | G17: Deite de bruços, junte as escápulas, mova os braços simulando um anjo na neve ao contrário, sem encolher os ombros | I17: Com fonte | K17: =COUNTIF(exercicio_equipamento!$A$2:$A$400,A17)>0 -> FALSE | L17: =COUNTIF(exercicio_alternativo!$A$2:$A$400,A17) -> 3
A18: 17 | B18: Puxada Alta | C18: Lat Pulldown | D18: Puxada da barra na polia alta até a parte superior do peito, sentado | E18: 2 | F18: 4 | G18: Puxe os cotovelos para baixo e para trás, levando a barra até abaixo do queixo; junte as escápulas no final; evite usar o corpo para dar embalo | H18: https://www.youtube.com/watch?v=mPmfwbc_svw | I18: Com fonte | K18: =COUNTIF(exercicio_equipamento!$A$2:$A$400,A18)>0 -> TRUE | L18: =COUNTIF(exercicio_alternativo!$A$2:$A$400,A18) -> 4
A19: 18 | B19: Remada Baixa | C19: Seated Cable Row | D19: Remada sentado na polia baixa com puxador triângulo, tronco ereto | E19: 1 | F19: 5 | G19: Mantenha o tronco ereto, cotovelos próximos ao corpo, puxe até o abdômen e junte as escápulas; não deixe os ombros subirem em direção às orelhas | H19: https://www.youtube.com/watch?v=f8AVh4VBbos | I19: Com fonte | K19: =COUNTIF(exercicio_equipamento!$A$2:$A$400,A19)>0 -> TRUE | L19: =COUNTIF(exercicio_alternativo!$A$2:$A$400,A19) -> 4
A20: 19 | B20: Remada Unilateral Articulada | C20: Machine One-Arm Row | D20: Remada em máquina articulada (iso-lateral) com apoio de peito, um braço por vez ou os dois juntos | E20: 2 | F20: 5 | G20: Mantenha o peito apoiado no encosto e puxe a manopla levando o cotovelo para trás; contraia por 1-2 s antes de voltar, sem girar o tronco | H20: https://www.youtube.com/watch?v=f8AVh4VBbos | I20: Com fonte | J20: Nível revisado de 1 para 2 na pesquisa - confirmar com professor | K20: =COUNTIF(exercicio_equipamento!$A$2:$A$400,A20)>0 -> TRUE | L20: =COUNTIF(exercicio_alternativo!$A$2:$A$400,A20) -> 4
A21: 20 | B21: Puxada Unilateral na Polia | C21: Single-Arm Cable Pulldown | D21: Puxada de um braço por vez na polia alta | E21: 2 | F21: 4 | G21: Sentado de frente para a polia alta, puxe o cabo com um braço até a altura do queixo/peito, controlando a volta | I21: Com fonte | K21: =COUNTIF(exercicio_equipamento!$A$2:$A$400,A21)>0 -> TRUE | L21: =COUNTIF(exercicio_alternativo!$A$2:$A$400,A21) -> 3
A22: 21 | B22: Remada Invertida | C22: Inverted Row | D22: Deitado sob uma barra baixa, puxa o peito até a barra com o corpo reto | E22: 1 | F22: 5 | G22: Deite-se sob uma barra na altura da cintura, pegada pronada, corpo reto, puxe o peito até a barra apertando as escápulas | I22: Com fonte | J22: Exige uma barra (barra baixa, Smith ou rack): conta como equipamento | K22: =COUNTIF(exercicio_equipamento!$A$2:$A$400,A22)>0 -> TRUE | L22: =COUNTIF(exercicio_alternativo!$A$2:$A$400,A22) -> 3
A23: 22 | B23: Barra Fixa | C23: Pull-up | D23: Pendurado na barra fixa, puxa o corpo para cima até o queixo passar da barra | E23: 3 | F23: 4 | G23: Pegada pronada, um pouco mais larga que os ombros; puxe até o queixo passar da barra, sem balançar as pernas | I23: Com fonte | J23: Barra fixa conta como equipamento | K23: =COUNTIF(exercicio_equipamento!$A$2:$A$400,A23)>0 -> TRUE | L23: =COUNTIF(exercicio_alternativo!$A$2:$A$400,A23) -> 3
A24: 23 | B24: Encolhimento com Halteres | C24: Dumbbell Shrug | D24: Eleva os ombros em direção às orelhas segurando halteres, sem flexionar os cotovelos | E24: 1 | F24: 6 | G24: Puxe os ombros para baixo e para trás antes de iniciar; suba só com os ombros (sem usar os braços), pausa breve no topo e desça controlado | I24: Com fonte | K24: =COUNTIF(exercicio_equipamento!$A$2:$A$400,A24)>0 -> TRUE | L24: =COUNTIF(exercicio_alternativo!$A$2:$A$400,A24) -> 3
A25: 24 | B25: Encolhimento com Barra | C25: Barbell Shrug | D25: Eleva os ombros em direção às orelhas segurando uma barra, sem flexionar os cotovelos | E25: 1 | F25: 6 | G25: Segure a barra à frente das coxas com pegada na largura dos ombros; eleve os ombros em direção às orelhas, pause e desça controlando | I25: Com fonte | K25: =COUNTIF(exercicio_equipamento!$A$2:$A$400,A25)>0 -> TRUE | L25: =COUNTIF(exercicio_alternativo!$A$2:$A$400,A25) -> 3
A26: 25 | B26: Elevação Prona em Y | C26: Prone Y-Raise | D26: Deitado de bruços, braços em Y acima da cabeça; levanta peito e braços do chão | E26: 1 | F26: 6 | G26: Deitado de bruços, braços estendidos em Y acima da cabeça; levante peito e braços do chão simultaneamente, segure 1-2s e desça controlado | I26: Com fonte | K26: =COUNTIF(exercicio_equipamento!$A$2:$A$400,A26)>0 -> FALSE | L26: =COUNTIF(exercicio_alternativo!$A$2:$A$400,A26) -> 3
A27: 26 | B27: Anjo e Diabo Prono | C27: Prone Angel and Devil | D27: Deitado de bruços, abre os braços em arco até a lombar, virando as palmas para cima | E27: 2 | F27: 6 | G27: Deitado de bruços, peito levantado, braços em posição de oração; abra os braços em arco até a lombar, virando as palmas para cima | I27: Com fonte | K27: =COUNTIF(exercicio_equipamento!$A$2:$A$400,A27)>0 -> FALSE | L27: =COUNTIF(exercicio_alternativo!$A$2:$A$400,A27) -> 3
A28: 27 | B28: Hiperextensão Lombar | C28: Back Extension | D28: Extensão de tronco em banco romano, apoiando quadril/pernas, sobe e desce o tronco | E28: 2 | F28: 18 | G28: Desça o tronco controlado, contraia os eretores da espinha para subir até formar uma linha reta da cabeça aos calcanhares; não hiperestenda além da linha neutra | I28: Com fonte | K28: =COUNTIF(exercicio_equipamento!$A$2:$A$400,A28)>0 -> TRUE | L28: =COUNTIF(exercicio_alternativo!$A$2:$A$400,A28) -> 3
A29: 28 | B29: Good Morning | C29: Good Morning | D29: Com a barra nas costas, flexiona o quadril levando o tronco à frente com a coluna reta | E29: 3 | F29: 13 | G29: Barra apoiada na parte superior das costas, flexione o quadril para frente mantendo a coluna reta até quase paralelo ao chão | I29: Com fonte | J29: A lombar trabalha principalmente de forma isométrica; motor primário é posterior de coxa/glúteos | K29: =COUNTIF(exercicio_equipamento!$A$2:$A$400,A29)>0 -> TRUE | L29: =COUNTIF(exercicio_alternativo!$A$2:$A$400,A29) -> 3
A30: 29 | B30: Superman | C30: Superman | D30: Deitado de bruços, levanta braços e pernas do chão ao mesmo tempo, trabalhando a lombar | E30: 1 | F30: 18 | G30: Deitado de bruços, pernas e braços estendidos; levante braços e pernas ~15cm do chão simultaneamente, contraindo glúteos, core e lombar; segure 2-3s | I30: Com fonte | K30: =COUNTIF(exercicio_equipamento!$A$2:$A$400,A30)>0 -> FALSE | L30: =COUNTIF(exercicio_alternativo!$A$2:$A$400,A30) -> 3
A31: 30 | B31: Rosca Direta na Polia Baixa | C31: Cable Biceps Curl | D31: Flexão de cotovelos em pé, puxando a barra (ou corda) da polia baixa | E31: 1 | F31: 7 | G31: Não deixe o braço ir para trás durante a subida; mantenha-o parado ou levemente à frente do tronco | H31: https://www.youtube.com/watch?v=zqklqTcOsbo | I31: Com fonte | K31: =COUNTIF(exercicio_equipamento!$A$2:$A$400,A31)>0 -> TRUE | L31: =COUNTIF(exercicio_alternativo!$A$2:$A$400,A31) -> 4
A32: 31 | B32: Rosca Scott na Máquina | C32: Machine Preacher Curl | D32: Flexão de cotovelos com apoio do braço em banco Scott (máquina), isola o bíceps | E32: 1 | F32: 7 | G32: Apoie bem a parte de trás do braço no banco para isolar o bíceps | H32: https://www.youtube.com/watch?v=dVKX-gyJYSI | I32: Com fonte | J32: Fonte parcial: conteúdo da página não pôde ser conferido - revisar | K32: =COUNTIF(exercicio_equipamento!$A$2:$A$400,A32)>0 -> TRUE | L32: =COUNTIF(exercicio_alternativo!$A$2:$A$400,A32) -> 3
A33: 32 | B33: Rosca Inclinada com Halteres | C33: Incline Dumbbell Curl | D33: Rosca de bíceps sentado em banco inclinado (45°), braços pendendo atrás do tronco | E33: 1 | F33: 7 | G33: Sente no banco inclinado e deixe os braços pendurados retos ao lado do corpo, levemente atrás do tronco; flexione só os cotovelos | H33: https://www.youtube.com/watch?v=Os0CbdSre6I | I33: Com fonte | K33: =COUNTIF(exercicio_equipamento!$A$2:$A$400,A33)>0 -> TRUE | L33: =COUNTIF(exercicio_alternativo!$A$2:$A$400,A33) -> 3
A34: 33 | B34: Rosca Scott com Halteres | C34: Dumbbell Preacher Curl | D34: Rosca de bíceps com o braço apoiado no banco Scott, usando halteres | E34: 1 | F34: 7 | G34: Um braço por vez, com a parte de trás do braço bem apoiada no banco Scott; permite corrigir desequilíbrios entre os lados | I34: Com fonte | K34: =COUNTIF(exercicio_equipamento!$A$2:$A$400,A34)>0 -> TRUE | L34: =COUNTIF(exercicio_alternativo!$A$2:$A$400,A34) -> 3
A35: 34 | B35: Rosca de Bíceps com Autorresistência | C35: Self-Resisted Biceps Curl | D35: Um braço faz a rosca contra a resistência da outra mão, sem nenhum objeto | E35: 1 | F35: 7 | G35: Com um braço, puxe o pulso do outro braço para baixo enquanto esse braço tenta flexionar o cotovelo contra essa resistência; alternar os lados. Eficácia reduzida comparada a exercícios com carga real | I35: Com fonte | J35: Eficácia reduzida vs. exercícios com carga; isolar bíceps sem objeto é limitado. Única opção sem equipamento para bíceps | K35: =COUNTIF(exercicio_equipamento!$A$2:$A$400,A35)>0 -> FALSE | L35: =COUNTIF(exercicio_alternativo!$A$2:$A$400,A35) -> 3
A36: 35 | B36: Tríceps Pulley | C36: Triceps Pushdown | D36: Extensão de cotovelos em pé na polia alta, com barra ou corda | E36: 1 | F36: 8 | G36: Comece com a barra na altura do peito e os cotovelos junto ao corpo; estenda só os antebraços, sem mover os cotovelos | H36: https://www.youtube.com/watch?v=2X15sDkPQc0 | I36: Com fonte | K36: =COUNTIF(exercicio_equipamento!$A$2:$A$400,A36)>0 -> TRUE | L36: =COUNTIF(exercicio_alternativo!$A$2:$A$400,A36) -> 4
A37: 36 | B37: Tríceps Testa na Polia | C37: Cable Skull Crusher | D37: Deitado em um banco de frente para a polia, estende os cotovelos puxando a barra ou corda da polia | E37: 2 | F37: 8 | G37: Desça a barra flexionando os cotovelos; perto da cabeça, leve os cotovelos levemente para trás para a barra passar | H37: https://www.youtube.com/watch?v=OxsOGLqk8M0 | I37: Com fonte | K37: =COUNTIF(exercicio_equipamento!$A$2:$A$400,A37)>0 -> TRUE | L37: =COUNTIF(exercicio_alternativo!$A$2:$A$400,A37) -> 3
A38: 37 | B38: Tríceps Francês na Polia | C38: Cable Overhead Triceps Extension | D38: De costas para a polia baixa, estende os cotovelos acima da cabeça puxando a corda | E38: 1 | F38: 8 | G38: Mantenha os cotovelos apontados para a frente, funcionando como um pivô fixo | H38: https://www.youtube.com/watch?v=PlQOxSm_ZWI | I38: Com fonte | K38: =COUNTIF(exercicio_equipamento!$A$2:$A$400,A38)>0 -> TRUE | L38: =COUNTIF(exercicio_alternativo!$A$2:$A$400,A38) -> 4
A39: 38 | B39: Rosca de Punho com Halteres | C39: Dumbbell Wrist Curl | D39: Flexão de punho (palmas para cima) com antebraços apoiados em um banco, halteres pendendo das mãos | E39: 1 | F39: 9 | G39: Apoie os antebraços no banco com os punhos soltos na ponta; flexione só o punho, sem mover o cotovelo; desça lentamente até o alongamento máximo | I39: Com fonte | K39: =COUNTIF(exercicio_equipamento!$A$2:$A$400,A39)>0 -> TRUE | L39: =COUNTIF(exercicio_alternativo!$A$2:$A$400,A39) -> 3
A40: 39 | B40: Rosca de Punho com Barra | C40: Barbell Wrist Curl | D40: Flexão de punho com barra reta ou W nas duas mãos, antebraços apoiados | E40: 1 | F40: 9 | G40: Antebraços apoiados no banco ou nas coxas, palmas para cima; flexione só os punhos e desça devagar até o alongamento | I40: Com fonte | K40: =COUNTIF(exercicio_equipamento!$A$2:$A$400,A40)>0 -> TRUE | L40: =COUNTIF(exercicio_alternativo!$A$2:$A$400,A40) -> 3
...

Sheet exercicio_alternativo
A1: exercicio_id | B1: alternativo_id | C1: ordem | D1: observacao | E1: _aux_exercicio | F1: _aux_alternativo | G1: _calc_alternativa_sem_equipamento
A2: 1 | B2: 4 | C2: 1 | E2: =IFERROR(INDEX(exercicio!$B$2:$B$190,MATCH(A2,exercicio!$A$2:$A$190,0)),"") -> Supino Reto com Barra | F2: =IFERROR(INDEX(exercicio!$B$2:$B$190,MATCH(B2,exercicio!$A$2:$A$190,0)),"") -> Flexão de Braço | G2: =COUNTIF(exercicio_equipamento!$A$2:$A$400,B2)=0 -> TRUE
A3: 1 | B3: 67 | C3: 2 | E3: =IFERROR(INDEX(exercicio!$B$2:$B$190,MATCH(A3,exercicio!$A$2:$A$190,0)),"") -> Supino Reto com Barra | F3: =IFERROR(INDEX(exercicio!$B$2:$B$190,MATCH(B3,exercicio!$A$2:$A$190,0)),"") -> Supino Reto com Halteres | G3: =COUNTIF(exercicio_equipamento!$A$2:$A$400,B3)=0 -> FALSE
A4: 1 | B4: 69 | C4: 3 | E4: =IFERROR(INDEX(exercicio!$B$2:$B$190,MATCH(A4,exercicio!$A$2:$A$190,0)),"") -> Supino Reto com Barra | F4: =IFERROR(INDEX(exercicio!$B$2:$B$190,MATCH(B4,exercicio!$A$2:$A$190,0)),"") -> Supino na Máquina | G4: =COUNTIF(exercicio_equipamento!$A$2:$A$400,B4)=0 -> FALSE
A5: 1 | B5: 2 | C5: 4 | E5: =IFERROR(INDEX(exercicio!$B$2:$B$190,MATCH(A5,exercicio!$A$2:$A$190,0)),"") -> Supino Reto com Barra | F5: =IFERROR(INDEX(exercicio!$B$2:$B$190,MATCH(B5,exercicio!$A$2:$A$190,0)),"") -> Supino Inclinado com Halteres | G5: =COUNTIF(exercicio_equipamento!$A$2:$A$400,B5)=0 -> FALSE
A6: 2 | B6: 6 | C6: 1 | E6: =IFERROR(INDEX(exercicio!$B$2:$B$190,MATCH(A6,exercicio!$A$2:$A$190,0)),"") -> Supino Inclinado com Halteres | F6: =IFERROR(INDEX(exercicio!$B$2:$B$190,MATCH(B6,exercicio!$A$2:$A$190,0)),"") -> Flexão com Pés Elevados | G6: =COUNTIF(exercicio_equipamento!$A$2:$A$400,B6)=0 -> TRUE
A7: 2 | B7: 68 | C7: 2 | E7: =IFERROR(INDEX(exercicio!$B$2:$B$190,MATCH(A7,exercicio!$A$2:$A$190,0)),"") -> Supino Inclinado com Halteres | F7: =IFERROR(INDEX(exercicio!$B$2:$B$190,MATCH(B7,exercicio!$A$2:$A$190,0)),"") -> Supino Inclinado com Barra | G7: =COUNTIF(exercicio_equipamento!$A$2:$A$400,B7)=0 -> FALSE
A8: 2 | B8: 70 | C8: 3 | E8: =IFERROR(INDEX(exercicio!$B$2:$B$190,MATCH(A8,exercicio!$A$2:$A$190,0)),"") -> Supino Inclinado com Halteres | F8: =IFERROR(INDEX(exercicio!$B$2:$B$190,MATCH(B8,exercicio!$A$2:$A$190,0)),"") -> Supino Inclinado na Máquina | G8: =COUNTIF(exercicio_equipamento!$A$2:$A$400,B8)=0 -> FALSE
A9: 2 | B9: 67 | C9: 4 | E9: =IFERROR(INDEX(exercicio!$B$2:$B$190,MATCH(A9,exercicio!$A$2:$A$190,0)),"") -> Supino Inclinado com Halteres | F9: =IFERROR(INDEX(exercicio!$B$2:$B$190,MATCH(B9,exercicio!$A$2:$A$190,0)),"") -> Supino Reto com Halteres | G9: =COUNTIF(exercicio_equipamento!$A$2:$A$400,B9)=0 -> FALSE
A10: 3 | B10: 5 | C10: 1 | E10: =IFERROR(INDEX(exercicio!$B$2:$B$190,MATCH(A10,exercicio!$A$2:$A$190,0)),"") -> Voador Peitoral | F10: =IFERROR(INDEX(exercicio!$B$2:$B$190,MATCH(B10,exercicio!$A$2:$A$190,0)),"") -> Flexão com Apoio Afastado | G10: =COUNTIF(exercicio_equipamento!$A$2:$A$400,B10)=0 -> TRUE
A11: 3 | B11: 72 | C11: 2 | E11: =IFERROR(INDEX(exercicio!$B$2:$B$190,MATCH(A11,exercicio!$A$2:$A$190,0)),"") -> Voador Peitoral | F11: =IFERROR(INDEX(exercicio!$B$2:$B$190,MATCH(B11,exercicio!$A$2:$A$190,0)),"") -> Crossover na Polia | G11: =COUNTIF(exercicio_equipamento!$A$2:$A$400,B11)=0 -> FALSE
A12: 3 | B12: 71 | C12: 3 | E12: =IFERROR(INDEX(exercicio!$B$2:$B$190,MATCH(A12,exercicio!$A$2:$A$190,0)),"") -> Voador Peitoral | F12: =IFERROR(INDEX(exercicio!$B$2:$B$190,MATCH(B12,exercicio!$A$2:$A$190,0)),"") -> Crucifixo Reto com Halteres | G12: =COUNTIF(exercicio_equipamento!$A$2:$A$400,B12)=0 -> FALSE
A13: 4 | B13: 5 | C13: 1 | E13: =IFERROR(INDEX(exercicio!$B$2:$B$190,MATCH(A13,exercicio!$A$2:$A$190,0)),"") -> Flexão de Braço | F13: =IFERROR(INDEX(exercicio!$B$2:$B$190,MATCH(B13,exercicio!$A$2:$A$190,0)),"") -> Flexão com Apoio Afastado | G13: =COUNTIF(exercicio_equipamento!$A$2:$A$400,B13)=0 -> TRUE
... A41: 11 | B41: 2 | C41: 3 | E41: =IFERROR(INDEX(exercicio!$B$2:$B$190,MATCH(A41,exercicio!$A$2:$A$190,0)),"") -> Desenvolvimento com Halteres | F41: =IFERROR(INDEX(exercicio!$B$2:$B$190,MATCH(B41,exercicio!$A$2:$A$190,0)),"") -> Supino Inclinado com Halteres | G41: =COUNTIF(exercicio_equipamento!$A$2:$A$400,B41)=0 -> FALSE
A42: 12 | B42: 15 | C42: 1 | D42: Aproximação: a elevação em T trabalha mais a porção posterior do deltoide | E42: =IFERROR(INDEX(exercicio!$B$2:$B$190,MATCH(A42,exercicio!$A$2:$A$190,0)),"") -> Elevação Lateral no Cabo | F42: =IFERROR(INDEX(exercicio!$B$2:$B$190,MATCH(B42,exercicio!$A$2:$A$190,0)),"") -> Elevação Prona em T | G42: =COUNTIF(exercicio_equipamento!$A$2:$A$400,B42)=0 -> TRUE
A43: 12 | B43: 73 | C43: 2 | E43: =IFERROR(INDEX(exercicio!$B$2:$B$190,MATCH(A43,exercicio!$A$2:$A$190,0)),"") -> Elevação Lateral no Cabo | F43: =IFERROR(INDEX(exercicio!$B$2:$B$190,MATCH(B43,exercicio!$A$2:$A$190,0)),"") -> Elevação Lateral com Halteres | G43: =COUNTIF(exercicio_equipamento!$A$2:$A$400,B43)=0 -> FALSE
A44: 12 | B44: 13 | C44: 3 | E44: =IFERROR(INDEX(exercicio!$B$2:$B$190,MATCH(A44,exercicio!$A$2:$A$190,0)),"") -> Elevação Lateral no Cabo | F44: =IFERROR(INDEX(exercicio!$B$2:$B$190,MATCH(B44,exercicio!$A$2:$A$190,0)),"") -> Elevação Lateral na Máquina | G44: =COUNTIF(exercicio_equipamento!$A$2:$A$400,B44)=0 -> FALSE
A45: 13 | B45: 15 | C45: 1 | D45: Aproximação: a elevação em T trabalha mais a porção posterior do deltoide | E45: =IFERROR(INDEX(exercicio!$B$2:$B$190,MATCH(A45,exercicio!$A$2:$A$190,0)),"") -> Elevação Lateral na Máquina | F45: =IFERROR(INDEX(exercicio!$B$2:$B$190,MATCH(B45,exercicio!$A$2:$A$190,0)),"") -> Elevação Prona em T | G45: =COUNTIF(exercicio_equipamento!$A$2:$A$400,B45)=0 -> TRUE
A46: 13 | B46: 73 | C46: 2 | E46: =IFERROR(INDEX(exercicio!$B$2:$B$190,MATCH(A46,exercicio!$A$2:$A$190,0)),"") -> Elevação Lateral na Máquina | F46: =IFERROR(INDEX(exercicio!$B$2:$B$190,MATCH(B46,exercicio!$A$2:$A$190,0)),"") -> Elevação Lateral com Halteres | G46: =COUNTIF(exercicio_equipamento!$A$2:$A$400,B46)=0 -> FALSE
A47: 13 | B47: 12 | C47: 3 | E47: =IFERROR(INDEX(exercicio!$B$2:$B$190,MATCH(A47,exercicio!$A$2:$A$190,0)),"") -> Elevação Lateral na Máquina | F47: =IFERROR(INDEX(exercicio!$B$2:$B$190,MATCH(B47,exercicio!$A$2:$A$190,0)),"") -> Elevação Lateral no Cabo | G47: =COUNTIF(exercicio_equipamento!$A$2:$A$400,B47)=0 -> FALSE
A48: 14 | B48: 16 | C48: 1 | E48: =IFERROR(INDEX(exercicio!$B$2:$B$190,MATCH(A48,exercicio!$A$2:$A$190,0)),"") -> Crucifixo Invertido na Polia | F48: =IFERROR(INDEX(exercicio!$B$2:$B$190,MATCH(B48,exercicio!$A$2:$A$190,0)),"") -> Anjo da Neve Invertido | G48: =COUNTIF(exercicio_equipamento!$A$2:$A$400,B48)=0 -> TRUE
A49: 14 | B49: 15 | C49: 2 | E49: =IFERROR(INDEX(exercicio!$B$2:$B$190,MATCH(A49,exercicio!$A$2:$A$190,0)),"") -> Crucifixo Invertido na Polia | F49: =IFERROR(INDEX(exercicio!$B$2:$B$190,MATCH(B49,exercicio!$A$2:$A$190,0)),"") -> Elevação Prona em T | G49: =COUNTIF(exercicio_equipamento!$A$2:$A$400,B49)=0 -> TRUE
A50: 14 | B50: 19 | C50: 3 | E50: =IFERROR(INDEX(exercicio!$B$2:$B$190,MATCH(A50,exercicio!$A$2:$A$190,0)),"") -> Crucifixo Invertido na Polia | F50: =IFERROR(INDEX(exercicio!$B$2:$B$190,MATCH(B50,exercicio!$A$2:$A$190,0)),"") -> Remada Unilateral Articulada | G50: =COUNTIF(exercicio_equipamento!$A$2:$A$400,B50)=0 -> FALSE
A51: 15 | B51: 16 | C51: 1 | E51: =IFERROR(INDEX(exercicio!$B$2:$B$190,MATCH(A51,exercicio!$A$2:$A$190,0)),"") -> Elevação Prona em T | F51: =IFERROR(INDEX(exercicio!$B$2:$B$190,MATCH(B51,exercicio!$A$2:$A$190,0)),"") -> Anjo da Neve Invertido | G51: =COUNTIF(exercicio_equipamento!$A$2:$A$400,B51)=0 -> TRUE
A52: 15 | B52: 25 | C52: 2 | E52: =IFERROR(INDEX(exercicio!$B$2:$B$190,MATCH(A52,exercicio!$A$2:$A$190,0)),"") -> Elevação Prona em T | F52: =IFERROR(INDEX(exercicio!$B$2:$B$190,MATCH(B52,exercicio!$A$2:$A$190,0)),"") -> Elevação Prona em Y | G52: =COUNTIF(exercicio_equipamento!$A$2:$A$400,B52)=0 -> TRUE
A53: 15 | B53: 14 | C53: 3 | E53: =IFERROR(INDEX(exercicio!$B$2:$B$190,MATCH(A53,exercicio!$A$2:$A$190,0)),"") -> Elevação Prona em T | F53: =IFERROR(INDEX(exercicio!$B$2:$B$190,MATCH(B53,exercicio!$A$2:$A$190,0)),"") -> Crucifixo Invertido na Polia | G53: =COUNTIF(exercicio_equipamento!$A$2:$A$400,B53)=0 -> FALSE
A54: 16 | B54: 15 | C54: 1 | E54: =IFERROR(INDEX(exercicio!$B$2:$B$190,MATCH(A54,exercicio!$A$2:$A$190,0)),"") -> Anjo da Neve Invertido | F54: =IFERROR(INDEX(exercicio!$B$2:$B$190,MATCH(B54,exercicio!$A$2:$A$190,0)),"") -> Elevação Prona em T | G54: =COUNTIF(exercicio_equipamento!$A$2:$A$400,B54)=0 -> TRUE
A55: 16 | B55: 29 | C55: 2 | E55: =IFERROR(INDEX(exercicio!$B$2:$B$190,MATCH(A55,exercicio!$A$2:$A$190,0)),"") -> Anjo da Neve Invertido | F55: =IFERROR(INDEX(exercicio!$B$2:$B$190,MATCH(B55,exercicio!$A$2:$A$190,0)),"") -> Superman | G55: =COUNTIF(exercicio_equipamento!$A$2:$A$400,B55)=0 -> TRUE
A56: 16 | B56: 14 | C56: 3 | E56: =IFERROR(INDEX(exercicio!$B$2:$B$190,MATCH(A56,exercicio!$A$2:$A$190,0)),"") -> Anjo da Neve Invertido | F56: =IFERROR(INDEX(exercicio!$B$2:$B$190,MATCH(B56,exercicio!$A$2:$A$190,0)),"") -> Crucifixo Invertido na Polia | G56: =COUNTIF(exercicio_equipamento!$A$2:$A$400,B56)=0 -> FALSE
A57: 17 | B57: 22 | C57: 1 | E57: =IFERROR(INDEX(exercicio!$B$2:$B$190,MATCH(A57,exercicio!$A$2:$A$190,0)),"") -> Puxada Alta | F57: =IFERROR(INDEX(exercicio!$B$2:$B$190,MATCH(B57,exercicio!$A$2:$A$190,0)),"") -> Barra Fixa | G57: =COUNTIF(exercicio_equipamento!$A$2:$A$400,B57)=0 -> FALSE
... A59: 17 | B59: 20 | C59: 3 | E59: =IFERROR(INDEX(exercicio!$B$2:$B$190,MATCH(A59,exercicio!$A$2:$A$190,0)),"") -> Puxada Alta | F59: =IFERROR(INDEX(exercicio!$B$2:$B$190,MATCH(B59,exercicio!$A$2:$A$190,0)),"") -> Puxada Unilateral na Polia | G59: =COUNTIF(exercicio_equipamento!$A$2:$A$400,B59)=0 -> FALSE
A60: 17 | B60: 25 | C60: 4 | D60: Aproximação: sem objeto não há puxada vertical equivalente; trabalha escápulas/costas altas | E60: =IFERROR(INDEX(exercicio!$B$2:$B$190,MATCH(A60,exercicio!$A$2:$A$190,0)),"") -> Puxada Alta | F60: =IFERROR(INDEX(exercicio!$B$2:$B$190,MATCH(B60,exercicio!$A$2:$A$190,0)),"") -> Elevação Prona em Y | G60: =COUNTIF(exercicio_equipamento!$A$2:$A$400,B60)=0 -> TRUE
A61: 18 | B61: 19 | C61: 1 | E61: =IFERROR(INDEX(exercicio!$B$2:$B$190,MATCH(A61,exercicio!$A$2:$A$190,0)),"") -> Remada Baixa | F61: =IFERROR(INDEX(exercicio!$B$2:$B$190,MATCH(B61,exercicio!$A$2:$A$190,0)),"") -> Remada Unilateral Articulada | G61: =COUNTIF(exercicio_equipamento!$A$2:$A$400,B61)=0 -> FALSE
A62: 18 | B62: 77 | C62: 2 | E62: =IFERROR(INDEX(exercicio!$B$2:$B$190,MATCH(A62,exercicio!$A$2:$A$190,0)),"") -> Remada Baixa | F62: =IFERROR(INDEX(exercicio!$B$2:$B$190,MATCH(B62,exercicio!$A$2:$A$190,0)),"") -> Remada Cavalinho | G62: =COUNTIF(exercicio_equipamento!$A$2:$A$400,B62)=0 -> FALSE
A63: 18 | B63: 21 | C63: 3 | E63: =IFERROR(INDEX(exercicio!$B$2:$B$190,MATCH(A63,exercicio!$A$2:$A$190,0)),"") -> Remada Baixa | F63: =IFERROR(INDEX(exercicio!$B$2:$B$190,MATCH(B63,exercicio!$A$2:$A$190,0)),"") -> Remada Invertida | G63: =COUNTIF(exercicio_equipamento!$A$2:$A$400,B63)=0 -> FALSE
A64: 18 | B64: 15 | C64: 4 | D64: Aproximação: sem objeto não há remada equivalente; trabalha retração escapular | E64: =IFERROR(INDEX(exercicio!$B$2:$B$190,MATCH(A64,exercicio!$A$2:$A$190,0)),"") -> Remada Baixa | F64: =IFERROR(INDEX(exercicio!$B$2:$B$190,MATCH(B64,exercicio!$A$2:$A$190,0)),"") -> Elevação Prona em T | G64: =COUNTIF(exercicio_equipamento!$A$2:$A$400,B64)=0 -> TRUE
A65: 19 | B65: 18 | C65: 1 | E65: =IFERROR(INDEX(exercicio!$B$2:$B$190,MATCH(A65,exercicio!$A$2:$A$190,0)),"") -> Remada Unilateral Articulada | F65: =IFERROR(INDEX(exercicio!$B$2:$B$190,MATCH(B65,exercicio!$A$2:$A$190,0)),"") -> Remada Baixa | G65: =COUNTIF(exercicio_equipamento!$A$2:$A$400,B65)=0 -> FALSE
A66: 19 | B66: 77 | C66: 2 | E66: =IFERROR(INDEX(exercicio!$B$2:$B$190,MATCH(A66,exercicio!$A$2:$A$190,0)),"") -> Remada Unilateral Articulada | F66: =IFERROR(INDEX(exercicio!$B$2:$B$190,MATCH(B66,exercicio!$A$2:$A$190,0)),"") -> Remada Cavalinho | G66: =COUNTIF(exercicio_equipamento!$A$2:$A$400,B66)=0 -> FALSE
A67: 19 | B67: 21 | C67: 3 | E67: =IFERROR(INDEX(exercicio!$B$2:$B$190,MATCH(A67,exercicio!$A$2:$A$190,0)),"") -> Remada Unilateral Articulada | F67: =IFERROR(INDEX(exercicio!$B$2:$B$190,MATCH(B67,exercicio!$A$2:$A$190,0)),"") -> Remada Invertida | G67: =COUNTIF(exercicio_equipamento!$A$2:$A$400,B67)=0 -> FALSE
A68: 19 | B68: 15 | C68: 4 | D68: Aproximação: sem objeto não há remada equivalente | E68: =IFERROR(INDEX(exercicio!$B$2:$B$190,MATCH(A68,exercicio!$A$2:$A$190,0)),"") -> Remada Unilateral Articulada | F68: =IFERROR(INDEX(exercicio!$B$2:$B$190,MATCH(B68,exercicio!$A$2:$A$190,0)),"") -> Elevação Prona em T | G68: =COUNTIF(exercicio_equipamento!$A$2:$A$400,B68)=0 -> TRUE
...

Sheet exercicio_grupo_muscular
A1: exercicio_id | B1: grupo_muscular_id | C1: papel | D1: _aux_exercicio | E1: _aux_grupo
A2: 1 | B2: 1 | C2: PRIMARIO | D2: =IFERROR(INDEX(exercicio!$B$2:$B$190,MATCH(A2,exercicio!$A$2:$A$190,0)),"") -> Supino Reto com Barra | E2: =IFERROR(INDEX(grupo_muscular!$C$2:$C$50,MATCH(B2,grupo_muscular!$A$2:$A$50,0)),"") -> Peitoral
A3: 1 | B3: 3 | C3: SECUNDARIO | D3: =IFERROR(INDEX(exercicio!$B$2:$B$190,MATCH(A3,exercicio!$A$2:$A$190,0)),"") -> Supino Reto com Barra | E3: =IFERROR(INDEX(grupo_muscular!$C$2:$C$50,MATCH(B3,grupo_muscular!$A$2:$A$50,0)),"") -> Tríceps
A4: 1 | B4: 2 | C4: SECUNDARIO | D4: =IFERROR(INDEX(exercicio!$B$2:$B$190,MATCH(A4,exercicio!$A$2:$A$190,0)),"") -> Supino Reto com Barra | E4: =IFERROR(INDEX(grupo_muscular!$C$2:$C$50,MATCH(B4,grupo_muscular!$A$2:$A$50,0)),"") -> Deltoides
A5: 2 | B5: 1 | C5: PRIMARIO | D5: =IFERROR(INDEX(exercicio!$B$2:$B$190,MATCH(A5,exercicio!$A$2:$A$190,0)),"") -> Supino Inclinado com Halteres | E5: =IFERROR(INDEX(grupo_muscular!$C$2:$C$50,MATCH(B5,grupo_muscular!$A$2:$A$50,0)),"") -> Peitoral
A6: 2 | B6: 3 | C6: SECUNDARIO | D6: =IFERROR(INDEX(exercicio!$B$2:$B$190,MATCH(A6,exercicio!$A$2:$A$190,0)),"") -> Supino Inclinado com Halteres | E6: =IFERROR(INDEX(grupo_muscular!$C$2:$C$50,MATCH(B6,grupo_muscular!$A$2:$A$50,0)),"") -> Tríceps
A7: 2 | B7: 2 | C7: SECUNDARIO | D7: =IFERROR(INDEX(exercicio!$B$2:$B$190,MATCH(A7,exercicio!$A$2:$A$190,0)),"") -> Supino Inclinado com Halteres | E7: =IFERROR(INDEX(grupo_muscular!$C$2:$C$50,MATCH(B7,grupo_muscular!$A$2:$A$50,0)),"") -> Deltoides
A8: 3 | B8: 1 | C8: PRIMARIO | D8: =IFERROR(INDEX(exercicio!$B$2:$B$190,MATCH(A8,exercicio!$A$2:$A$190,0)),"") -> Voador Peitoral | E8: =IFERROR(INDEX(grupo_muscular!$C$2:$C$50,MATCH(B8,grupo_muscular!$A$2:$A$50,0)),"") -> Peitoral
A9: 3 | B9: 2 | C9: SECUNDARIO | D9: =IFERROR(INDEX(exercicio!$B$2:$B$190,MATCH(A9,exercicio!$A$2:$A$190,0)),"") -> Voador Peitoral | E9: =IFERROR(INDEX(grupo_muscular!$C$2:$C$50,MATCH(B9,grupo_muscular!$A$2:$A$50,0)),"") -> Deltoides
A10: 4 | B10: 1 | C10: PRIMARIO | D10: =IFERROR(INDEX(exercicio!$B$2:$B$190,MATCH(A10,exercicio!$A$2:$A$190,0)),"") -> Flexão de Braço | E10: =IFERROR(INDEX(grupo_muscular!$C$2:$C$50,MATCH(B10,grupo_muscular!$A$2:$A$50,0)),"") -> Peitoral
A11: 4 | B11: 3 | C11: SECUNDARIO | D11: =IFERROR(INDEX(exercicio!$B$2:$B$190,MATCH(A11,exercicio!$A$2:$A$190,0)),"") -> Flexão de Braço | E11: =IFERROR(INDEX(grupo_muscular!$C$2:$C$50,MATCH(B11,grupo_muscular!$A$2:$A$50,0)),"") -> Tríceps
A12: 4 | B12: 2 | C12: SECUNDARIO | D12: =IFERROR(INDEX(exercicio!$B$2:$B$190,MATCH(A12,exercicio!$A$2:$A$190,0)),"") -> Flexão de Braço | E12: =IFERROR(INDEX(grupo_muscular!$C$2:$C$50,MATCH(B12,grupo_muscular!$A$2:$A$50,0)),"") -> Deltoides
A13: 4 | B13: 9 | C13: SECUNDARIO | D13: =IFERROR(INDEX(exercicio!$B$2:$B$190,MATCH(A13,exercicio!$A$2:$A$190,0)),"") -> Flexão de Braço | E13: =IFERROR(INDEX(grupo_muscular!$C$2:$C$50,MATCH(B13,grupo_muscular!$A$2:$A$50,0)),"") -> Abdômen
... A189: 89 | B189: 14 | C189: SECUNDARIO | D189: =IFERROR(INDEX(exercicio!$B$2:$B$190,MATCH(A189,exercicio!$A$2:$A$190,0)),"") -> Afundo Lateral | E189: =IFERROR(INDEX(grupo_muscular!$C$2:$C$50,MATCH(B189,grupo_muscular!$A$2:$A$50,0)),"") -> Adutores

Sheet exercicio_equipamento
A1: exercicio_id | B1: equipamento_id | C1: _aux_exercicio | D1: _aux_equipamento
A2: 1 | B2: 1 | C2: =IFERROR(INDEX(exercicio!$B$2:$B$190,MATCH(A2,exercicio!$A$2:$A$190,0)),"") -> Supino Reto com Barra | D2: =IFERROR(INDEX(equipamento!$B$2:$B$50,MATCH(B2,equipamento!$A$2:$A$50,0)),"") -> Barra reta
A3: 1 | B3: 3 | C3: =IFERROR(INDEX(exercicio!$B$2:$B$190,MATCH(A3,exercicio!$A$2:$A$190,0)),"") -> Supino Reto com Barra | D3: =IFERROR(INDEX(equipamento!$B$2:$B$50,MATCH(B3,equipamento!$A$2:$A$50,0)),"") -> Banco reto
A4: 2 | B4: 4 | C4: =IFERROR(INDEX(exercicio!$B$2:$B$190,MATCH(A4,exercicio!$A$2:$A$190,0)),"") -> Supino Inclinado com Halteres | D4: =IFERROR(INDEX(equipamento!$B$2:$B$50,MATCH(B4,equipamento!$A$2:$A$50,0)),"") -> Banco ajustável
A5: 2 | B5: 2 | C5: =IFERROR(INDEX(exercicio!$B$2:$B$190,MATCH(A5,exercicio!$A$2:$A$190,0)),"") -> Supino Inclinado com Halteres | D5: =IFERROR(INDEX(equipamento!$B$2:$B$50,MATCH(B5,equipamento!$A$2:$A$50,0)),"") -> Halteres
A6: 3 | B6: 12 | C6: =IFERROR(INDEX(exercicio!$B$2:$B$190,MATCH(A6,exercicio!$A$2:$A$190,0)),"") -> Voador Peitoral | D6: =IFERROR(INDEX(equipamento!$B$2:$B$50,MATCH(B6,equipamento!$A$2:$A$50,0)),"") -> Peck deck
A7: 7 | B7: 8 | C7: =IFERROR(INDEX(exercicio!$B$2:$B$190,MATCH(A7,exercicio!$A$2:$A$190,0)),"") -> Mergulho em Paralelas | D7: =IFERROR(INDEX(equipamento!$B$2:$B$50,MATCH(B7,equipamento!$A$2:$A$50,0)),"") -> Barras paralelas
A8: 11 | B8: 4 | C8: =IFERROR(INDEX(exercicio!$B$2:$B$190,MATCH(A8,exercicio!$A$2:$A$190,0)),"") -> Desenvolvimento com Halteres | D8: =IFERROR(INDEX(equipamento!$B$2:$B$50,MATCH(B8,equipamento!$A$2:$A$50,0)),"") -> Banco ajustável
A9: 11 | B9: 2 | C9: =IFERROR(INDEX(exercicio!$B$2:$B$190,MATCH(A9,exercicio!$A$2:$A$190,0)),"") -> Desenvolvimento com Halteres | D9: =IFERROR(INDEX(equipamento!$B$2:$B$50,MATCH(B9,equipamento!$A$2:$A$50,0)),"") -> Halteres
A10: 12 | B10: 11 | C10: =IFERROR(INDEX(exercicio!$B$2:$B$190,MATCH(A10,exercicio!$A$2:$A$190,0)),"") -> Elevação Lateral no Cabo | D10: =IFERROR(INDEX(equipamento!$B$2:$B$50,MATCH(B10,equipamento!$A$2:$A$50,0)),"") -> Polia (cabo)
A11: 13 | B11: 15 | C11: =IFERROR(INDEX(exercicio!$B$2:$B$190,MATCH(A11,exercicio!$A$2:$A$190,0)),"") -> Elevação Lateral na Máquina | D11: =IFERROR(INDEX(equipamento!$B$2:$B$50,MATCH(B11,equipamento!$A$2:$A$50,0)),"") -> Máquina de elevação lateral
A12: 14 | B12: 11 | C12: =IFERROR(INDEX(exercicio!$B$2:$B$190,MATCH(A12,exercicio!$A$2:$A$190,0)),"") -> Crucifixo Invertido na Polia | D12: =IFERROR(INDEX(equipamento!$B$2:$B$50,MATCH(B12,equipamento!$A$2:$A$50,0)),"") -> Polia (cabo)
A13: 17 | B13: 11 | C13: =IFERROR(INDEX(exercicio!$B$2:$B$190,MATCH(A13,exercicio!$A$2:$A$190,0)),"") -> Puxada Alta | D13: =IFERROR(INDEX(equipamento!$B$2:$B$50,MATCH(B13,equipamento!$A$2:$A$50,0)),"") -> Polia (cabo)
... A78: 86 | B78: 31 | C78: =IFERROR(INDEX(exercicio!$B$2:$B$190,MATCH(A78,exercicio!$A$2:$A$190,0)),"") -> Cadeira Abdutora | D78: =IFERROR(INDEX(equipamento!$B$2:$B$50,MATCH(B78,equipamento!$A$2:$A$50,0)),"") -> Cadeira abdutora

Sheet exercicio_passo
A1: exercicio_id | B1: ordem | C1: descricao | D1: dica_extra | E1: _aux_exercicio
A2: 1 | B2: 1 | C2: Deite no banco com os pés apoiados no chão e retire a barra do suporte | D2: Mantenha as escápulas retraídas contra o banco | E2: =IFERROR(INDEX(exercicio!$B$2:$B$190,MATCH(A2,exercicio!$A$2:$A$190,0)),"") -> Supino Reto com Barra
A3: 2 | B3: 1 | C3: Ajuste o banco para uma inclinação de 30°. Sente-se no banco e apoie cada halter em cima dos joelhos | E3: =IFERROR(INDEX(exercicio!$B$2:$B$190,MATCH(A3,exercicio!$A$2:$A$190,0)),"") -> Supino Inclinado com Halteres
A4: 2 | B4: 2 | C4: Para deitar com segurança, use as coxas para impulsionar os halteres para cima, um de cada vez, enquanto deita as costas no banco | E4: =IFERROR(INDEX(exercicio!$B$2:$B$190,MATCH(A4,exercicio!$A$2:$A$190,0)),"") -> Supino Inclinado com Halteres
A5: 2 | B5: 3 | C5: Mantenha os pés firmes no chão para dar estabilidade e feche as escápulas | E5: =IFERROR(INDEX(exercicio!$B$2:$B$190,MATCH(A5,exercicio!$A$2:$A$190,0)),"") -> Supino Inclinado com Halteres
A6: 2 | B6: 4 | C6: Desça os halteres de forma controlada até o lado do seu peitoral superior | E6: =IFERROR(INDEX(exercicio!$B$2:$B$190,MATCH(A6,exercicio!$A$2:$A$190,0)),"") -> Supino Inclinado com Halteres
A7: 2 | B7: 5 | C7: Empurre os halteres para cima com força, concentrando o esforço no peitoral | D7: Evite esticar o cotovelo completamente no topo para não tirar o estímulo do peito | E7: =IFERROR(INDEX(exercicio!$B$2:$B$190,MATCH(A7,exercicio!$A$2:$A$190,0)),"") -> Supino Inclinado com Halteres
A8: 3 | B8: 1 | C8: Regule a altura do assento para que as manoplas fiquem exatamente na linha do meio do seu peitoral | E8: =IFERROR(INDEX(exercicio!$B$2:$B$190,MATCH(A8,exercicio!$A$2:$A$190,0)),"") -> Voador Peitoral
A9: 3 | B9: 2 | C9: Posicione os braços da máquina em uma abertura que permita alongar o peitoral | E9: =IFERROR(INDEX(exercicio!$B$2:$B$190,MATCH(A9,exercicio!$A$2:$A$190,0)),"") -> Voador Peitoral
A10: 3 | B10: 3 | C10: Pressione as manoplas para a frente até que se aproximem na frente do peito | E10: =IFERROR(INDEX(exercicio!$B$2:$B$190,MATCH(A10,exercicio!$A$2:$A$190,0)),"") -> Voador Peitoral
A11: 3 | B11: 4 | C11: Retorne os braços de forma lenta e controlada até sentir o peitoral alongar bem | E11: =IFERROR(INDEX(exercicio!$B$2:$B$190,MATCH(A11,exercicio!$A$2:$A$190,0)),"") -> Voador Peitoral
A12: 17 | B12: 1 | C12: Puxe a barra em direção à parte superior do peito | E12: =IFERROR(INDEX(exercicio!$B$2:$B$190,MATCH(A12,exercicio!$A$2:$A$190,0)),"") -> Puxada Alta
A13: 17 | B13: 2 | C13: Faça uma breve pausa de 1 segundo mantendo a musculatura das costas contraída | E13: =IFERROR(INDEX(exercicio!$B$2:$B$190,MATCH(A13,exercicio!$A$2:$A$190,0)),"") -> Puxada Alta
A14: 17 | B14: 3 | C14: Suba a barra de forma controlada | E14: =IFERROR(INDEX(exercicio!$B$2:$B$190,MATCH(A14,exercicio!$A$2:$A$190,0)),"") -> Puxada Alta

Sheet exercicio_apelido
A1: exercicio_id | B1: apelido | C1: _aux_exercicio
A2: 1 | B2: Bench Press | C2: =IFERROR(INDEX(exercicio!$B$2:$B$190,MATCH(A2,exercicio!$A$2:$A$190,0)),"") -> Supino Reto com Barra
A3: 1 | B3: Supino Reto | C3: =IFERROR(INDEX(exercicio!$B$2:$B$190,MATCH(A3,exercicio!$A$2:$A$190,0)),"") -> Supino Reto com Barra
A4: 1 | B4: Supino com Barra | C4: =IFERROR(INDEX(exercicio!$B$2:$B$190,MATCH(A4,exercicio!$A$2:$A$190,0)),"") -> Supino Reto com Barra
A5: 2 | B5: Supino 45 com Halteres | C5: =IFERROR(INDEX(exercicio!$B$2:$B$190,MATCH(A5,exercicio!$A$2:$A$190,0)),"") -> Supino Inclinado com Halteres
A6: 2 | B6: Supino Inclinado com Halter | C6: =IFERROR(INDEX(exercicio!$B$2:$B$190,MATCH(A6,exercicio!$A$2:$A$190,0)),"") -> Supino Inclinado com Halteres
A7: 3 | B7: Peck Deck | C7: =IFERROR(INDEX(exercicio!$B$2:$B$190,MATCH(A7,exercicio!$A$2:$A$190,0)),"") -> Voador Peitoral
A8: 3 | B8: Crucifixo na Máquina | C8: =IFERROR(INDEX(exercicio!$B$2:$B$190,MATCH(A8,exercicio!$A$2:$A$190,0)),"") -> Voador Peitoral
A9: 3 | B9: Pec Deck | C9: =IFERROR(INDEX(exercicio!$B$2:$B$190,MATCH(A9,exercicio!$A$2:$A$190,0)),"") -> Voador Peitoral
A10: 4 | B10: Push-up | C10: =IFERROR(INDEX(exercicio!$B$2:$B$190,MATCH(A10,exercicio!$A$2:$A$190,0)),"") -> Flexão de Braço
A11: 4 | B11: Apoio | C11: =IFERROR(INDEX(exercicio!$B$2:$B$190,MATCH(A11,exercicio!$A$2:$A$190,0)),"") -> Flexão de Braço
A12: 5 | B12: Flexão Larga | C12: =IFERROR(INDEX(exercicio!$B$2:$B$190,MATCH(A12,exercicio!$A$2:$A$190,0)),"") -> Flexão com Apoio Afastado
A13: 6 | B13: Flexão Declinada | C13: =IFERROR(INDEX(exercicio!$B$2:$B$190,MATCH(A13,exercicio!$A$2:$A$190,0)),"") -> Flexão com Pés Elevados
... A135: 89 | B135: Lateral Lunge | C135: =IFERROR(INDEX(exercicio!$B$2:$B$190,MATCH(A135,exercicio!$A$2:$A$190,0)),"") -> Afundo Lateral

Sheet exercicio_fonte
A1: exercicio_id | B1: fonte_id | C1: _aux_exercicio | D1: _aux_fonte
A2: 1 | B2: 1 | C2: =IFERROR(INDEX(exercicio!$B$2:$B$190,MATCH(A2,exercicio!$A$2:$A$190,0)),"") -> Supino Reto com Barra | D2: =IFERROR(INDEX(fonte!$B$2:$B$200,MATCH(B2,fonte!$A$2:$A$200,0))&" - "&INDEX(fonte!$C$2:$C$200,MATCH(B2,fonte!$A$2:$A$200,0)),"") -> JOI Rehab & Sports Medicine - Proper Bench Press Technique
A3: 2 | B3: 2 | C3: =IFERROR(INDEX(exercicio!$B$2:$B$190,MATCH(A3,exercicio!$A$2:$A$190,0)),"") -> Supino Inclinado com Halteres | D3: =IFERROR(INDEX(fonte!$B$2:$B$200,MATCH(B3,fonte!$A$2:$A$200,0))&" - "&INDEX(fonte!$C$2:$C$200,MATCH(B3,fonte!$A$2:$A$200,0)),"") -> NASM - Two-Arm Incline Dumbbell Chest Press
A4: 3 | B4: 80 | C4: =IFERROR(INDEX(exercicio!$B$2:$B$190,MATCH(A4,exercicio!$A$2:$A$190,0)),"") -> Voador Peitoral | D4: =IFERROR(INDEX(fonte!$B$2:$B$200,MATCH(B4,fonte!$A$2:$A$200,0))&" - "&INDEX(fonte!$C$2:$C$200,MATCH(B4,fonte!$A$2:$A$200,0)),"") -> StrengthLog - Pec Deck
A5: 4 | B5: 81 | C5: =IFERROR(INDEX(exercicio!$B$2:$B$190,MATCH(A5,exercicio!$A$2:$A$190,0)),"") -> Flexão de Braço | D5: =IFERROR(INDEX(fonte!$B$2:$B$200,MATCH(B5,fonte!$A$2:$A$200,0))&" - "&INDEX(fonte!$C$2:$C$200,MATCH(B5,fonte!$A$2:$A$200,0)),"") -> ACE Fitness - Push-Up (#41)
A6: 4 | B6: 82 | C6: =IFERROR(INDEX(exercicio!$B$2:$B$190,MATCH(A6,exercicio!$A$2:$A$190,0)),"") -> Flexão de Braço | D6: =IFERROR(INDEX(fonte!$B$2:$B$200,MATCH(B6,fonte!$A$2:$A$200,0))&" - "&INDEX(fonte!$C$2:$C$200,MATCH(B6,fonte!$A$2:$A$200,0)),"") -> StrengthLog - Push-Up
A7: 5 | B7: 3 | C7: =IFERROR(INDEX(exercicio!$B$2:$B$190,MATCH(A7,exercicio!$A$2:$A$190,0)),"") -> Flexão com Apoio Afastado | D7: =IFERROR(INDEX(fonte!$B$2:$B$200,MATCH(B7,fonte!$A$2:$A$200,0))&" - "&INDEX(fonte!$C$2:$C$200,MATCH(B7,fonte!$A$2:$A$200,0)),"") -> Healthline - Wide Push-Ups
A8: 6 | B8: 3 | C8: =IFERROR(INDEX(exercicio!$B$2:$B$190,MATCH(A8,exercicio!$A$2:$A$190,0)),"") -> Flexão com Pés Elevados | D8: =IFERROR(INDEX(fonte!$B$2:$B$200,MATCH(B8,fonte!$A$2:$A$200,0))&" - "&INDEX(fonte!$C$2:$C$200,MATCH(B8,fonte!$A$2:$A$200,0)),"") -> Healthline - Wide Push-Ups
A9: 7 | B9: 24 | C9: =IFERROR(INDEX(exercicio!$B$2:$B$190,MATCH(A9,exercicio!$A$2:$A$190,0)),"") -> Mergulho em Paralelas | D9: =IFERROR(INDEX(fonte!$B$2:$B$200,MATCH(B9,fonte!$A$2:$A$200,0))&" - "&INDEX(fonte!$C$2:$C$200,MATCH(B9,fonte!$A$2:$A$200,0)),"") -> FitnessVolt - Parallel Bar Dip Alternatives
A10: 7 | B10: 99 | C10: =IFERROR(INDEX(exercicio!$B$2:$B$190,MATCH(A10,exercicio!$A$2:$A$190,0)),"") -> Mergulho em Paralelas | D10: =IFERROR(INDEX(fonte!$B$2:$B$200,MATCH(B10,fonte!$A$2:$A$200,0))&" - "&INDEX(fonte!$C$2:$C$200,MATCH(B10,fonte!$A$2:$A$200,0)),"") -> StrengthLog - Bar Dip
A11: 8 | B11: 22 | C11: =IFERROR(INDEX(exercicio!$B$2:$B$190,MATCH(A11,exercicio!$A$2:$A$190,0)),"") -> Flexão Diamante | D11: =IFERROR(INDEX(fonte!$B$2:$B$200,MATCH(B11,fonte!$A$2:$A$200,0))&" - "&INDEX(fonte!$C$2:$C$200,MATCH(B11,fonte!$A$2:$A$200,0)),"") -> Exercise.com - Close-Grip Push-Up
A12: 8 | B12: 23 | C12: =IFERROR(INDEX(exercicio!$B$2:$B$190,MATCH(A12,exercicio!$A$2:$A$190,0)),"") -> Flexão Diamante | D12: =IFERROR(INDEX(fonte!$B$2:$B$200,MATCH(B12,fonte!$A$2:$A$200,0))&" - "&INDEX(fonte!$C$2:$C$200,MATCH(B12,fonte!$A$2:$A$200,0)),"") -> ExRx.net - Bodyweight Close Grip Push-up
A13: 9 | B13: 8 | C13: =IFERROR(INDEX(exercicio!$B$2:$B$190,MATCH(A13,exercicio!$A$2:$A$190,0)),"") -> Flexão em Pique | D13: =IFERROR(INDEX(fonte!$B$2:$B$200,MATCH(B13,fonte!$A$2:$A$200,0))&" - "&INDEX(fonte!$C$2:$C$200,MATCH(B13,fonte!$A$2:$A$200,0)),"") -> NASM - Pike Push-Up
... A106: 89 | B106: 79 | C106: =IFERROR(INDEX(exercicio!$B$2:$B$190,MATCH(A106,exercicio!$A$2:$A$190,0)),"") -> Afundo Lateral | D106: =IFERROR(INDEX(fonte!$B$2:$B$200,MATCH(B106,fonte!$A$2:$A$200,0))&" - "&INDEX(fonte!$C$2:$C$200,MATCH(B106,fonte!$A$2:$A$200,0)),"") -> ACE Fitness - A Guide to At-Home Workouts for Beginners (inclui afundo lateral)

Sheet grupo_muscular
A1: id | B1: codigo | C1: nome | D1: regiao | E1: descricao
A2: 1 | B2: PEITORAL | C2: Peitoral | D2: Superior | E2: Músculos do peito
A3: 2 | B3: DELTOIDES | C3: Deltoides | D3: Superior | E3: Ombros
A4: 3 | B4: TRICEPS | C4: Tríceps | D4: Superior | E4: Parte de trás do braço
A5: 4 | B5: BICEPS | C5: Bíceps | D5: Superior | E5: Parte da frente do braço
A6: 5 | B6: ANTEBRACO | C6: Antebraço | D6: Superior | E6: Antebraço e preensão
A7: 6 | B7: DORSAL | C7: Dorsal | D7: Superior | E7: Costas, região lateral (latíssimo do dorso)
A8: 7 | B8: TRAPEZIO | C8: Trapézio | D8: Superior | E8: Costas, região superior
A9: 8 | B9: LOMBAR | C9: Lombar | D9: Core | E9: Região inferior das costas
A10: 9 | B10: ABDOMEN | C10: Abdômen | D10: Core | E10: Core / abdominais
A11: 10 | B11: QUADRICEPS | C11: Quadríceps | D11: Inferior | E11: Frente da coxa
A12: 11 | B12: POSTERIOR_COXA | C12: Posterior de coxa | D12: Inferior | E12: Isquiotibiais
A13: 12 | B13: GLUTEOS | C13: Glúteos | D13: Inferior | E13: Região do quadril/glúteo
... A15: 14 | B15: ADUTORES | C15: Adutores | D15: Inferior | E15: Parte interna da coxa

Sheet equipamento
A1: id | B1: nome | C1: categoria | D1: descricao
A2: 1 | B2: Barra reta | C2: Peso livre | D2: Barra olímpica/reta para supino, agachamento, terra etc.
A3: 2 | B3: Halteres | C3: Peso livre
A4: 3 | B4: Banco reto | C4: Acessório | D4: Banco plano; também serve de apoio (ex.: agachamento búlgaro)
A5: 4 | B5: Banco ajustável | C5: Acessório | D5: Banco com encosto regulável (inclinado/vertical)
A6: 5 | B6: Banco Scott | C6: Acessório | D6: Apoio para o braço na rosca Scott
A7: 6 | B7: Roda abdominal | C7: Acessório
A8: 7 | B8: Barra fixa | C8: Estrutura fixa | D8: Barra para pendurar-se; também usada em barra baixa/Smith na remada invertida
A9: 8 | B9: Barras paralelas | C9: Estrutura fixa
A10: 9 | B10: Cadeira capitão | C10: Estrutura fixa | D10: Apoio de antebraços e costas para elevação de pernas
A11: 10 | B11: Banco romano | C11: Estrutura fixa | D11: Banco de hiperextensão lombar
A12: 11 | B12: Polia (cabo) | C12: Máquina | D12: Polia alta/baixa/cross-over; inclui acessórios (corda, barra, triângulo)
A13: 12 | B13: Peck deck | C13: Máquina | D13: Máquina do voador peitoral
A14: 13 | B14: Máquina de remada | C14: Máquina
A15: 14 | B15: Máquina de rosca Scott | C15: Máquina
A16: 15 | B16: Máquina de elevação lateral | C16: Máquina
A17: 16 | B17: Cadeira extensora | C17: Máquina
A18: 17 | B18: Cadeira flexora | C18: Máquina
A19: 18 | B19: Leg press | C19: Máquina
A20: 19 | B20: Máquina de panturrilha em pé | C20: Máquina | D20: Elevação de panturrilha em pé com apoio nos ombros
A21: 20 | B21: Máquina de abdominal | C21: Máquina
A22: 21 | B22: Barra W | C22: Peso livre | D22: Barra com pegada angulada (EZ)
A23: 22 | B23: Máquina Smith | C23: Máquina | D23: Barra guiada em trilhos
A24: 23 | B24: Máquina de supino | C24: Máquina | D24: Supino sentado (chest press)
A25: 24 | B25: Máquina de supino inclinado | C25: Máquina
A26: 25 | B26: Máquina de desenvolvimento | C26: Máquina | D26: Desenvolvimento de ombros (shoulder press)
A27: 26 | B27: Máquina de remada cavalinho | C27: Máquina | D27: Barra T / remada cavalinho com apoio
A28: 27 | B28: Mesa flexora | C28: Máquina | D28: Flexão de joelhos deitado
A29: 28 | B29: Máquina de panturrilha sentado | C29: Máquina | D29: Panturrilha sentado com apoio nos joelhos
A30: 29 | B30: Máquina de agachamento hack | C30: Máquina
A31: 30 | B31: Cadeira adutora | C31: Máquina
A32: 31 | B32: Cadeira abdutora | C32: Máquina

Sheet padrao_movimento
A1: id | B1: codigo | C1: nome
A2: 1 | B2: EMPURRAR_HORIZONTAL | C2: Empurrar horizontal
A3: 2 | B3: EMPURRAR_VERTICAL | C3: Empurrar vertical
A4: 3 | B4: ABDUCAO_ADUCAO_OMBRO | C4: Abdução/adução de ombro
A5: 4 | B5: PUXAR_VERTICAL | C5: Puxar vertical
A6: 5 | B6: PUXAR_HORIZONTAL | C6: Puxar horizontal
A7: 6 | B7: ELEVACAO_ESCAPULAR | C7: Elevação escapular
A8: 7 | B8: FLEXAO_COTOVELO | C8: Flexão de cotovelo
A9: 8 | B9: EXTENSAO_COTOVELO | C9: Extensão de cotovelo
A10: 9 | B10: PREENSAO_PUNHO | C10: Preensão e punho
A11: 10 | B11: AGACHAR | C11: Agachar / avançar
A12: 11 | B12: EXTENSAO_JOELHO | C12: Extensão de joelho
A13: 12 | B13: FLEXAO_JOELHO | C13: Flexão de joelho
... A21: 20 | B21: ABDUCAO_ADUCAO_QUADRIL | C21: Abdução/adução de quadril

Sheet nivel_dificuldade
A1: id | B1: nome | C1: descricao
A2: 1 | B2: Iniciante | C2: Movimento simples, baixo risco de lesão, ideal para quem nunca treinou
A3: 2 | B3: Intermediário | C3: Exige coordenação, controle do peso corporal ou técnica moderada
A4: 3 | B4: Avançado | C4: Exige força, equilíbrio ou mobilidade significativos; maior risco se mal executado

Sheet fonte
A1: id | B1: autor_organizacao | C1: titulo | D1: url | E1: tipo
A2: 1 | B2: JOI Rehab & Sports Medicine | C2: Proper Bench Press Technique | D2: https://www.joionline.net/?p=31037 | E2: Artigo técnico
A3: 2 | B3: NASM | C3: Two-Arm Incline Dumbbell Chest Press | D3: https://www.nasm.org/resource-center/exercise-library/two-arm-incline-dumbbell-chest-press | E3: Biblioteca de exercícios
A4: 3 | B4: Healthline | C4: Wide Push-Ups | D4: https://www.healthline.com/health/exercise-fitness/wide-pushups | E4: Artigo técnico (revisão médica)
A5: 4 | B5: StrengthLog | C5: Cable Lateral Raise | D5: https://www.strengthlog.com/cable-lateral-raise/ | E5: Biblioteca de exercícios
A6: 5 | B6: Physitrack | C6: Step-by-step guide to T raises | D6: https://www.physitrack.com/da/exercise-library/how-to-perform-the-t-raises | E6: Biblioteca clínica (fisioterapia)
A7: 6 | B7: GymKee | C7: Lateral Raise Machine | D7: https://gymkee.com/exercises/shoulders/lateral-raise-machine/ | E7: Biblioteca de exercícios
A8: 7 | B8: Fitbod | C8: Dumbbell Shoulder Press | D8: https://fitbod.me/exercises/dumbbell-shoulder-press | E8: Biblioteca de exercícios (app)
A9: 8 | B9: NASM | C9: Pike Push-Up | D9: https://www.nasm.org/resource-center/exercise-library/pike-push-up | E9: Biblioteca de exercícios
A10: 9 | B10: ACE Fitness | C10: Reverse Fly | D10: https://www.acefitness.org/resources/everyone/exercise-library/353/reverse-fly/ | E10: Biblioteca de exercícios (American Council on Exercise)
A11: 10 | B11: GoFitify | C11: Reverse Snow Angels | D11: https://gofitify.com/exercises/bodyweight/reverse-snow-angels | E11: Biblioteca de exercícios
A12: 11 | B12: StrengthLog | C12: How to Do Machine Lat Pulldown | D12: https://www.strengthlog.com/machine-lat-pulldown/ | E12: Biblioteca de exercícios
A13: 12 | B13: Healthline | C13: How to Do the Seated Row | D13: https://www.healthline.com/health/seated-row | E13: Artigo técnico
... A101: 100 | B101: StrengthLog | C101: Standing Calf Raise (machine) | D101: https://www.strengthlog.com/standing-calf-raise/ | E101: Biblioteca de exercícios

Sheet checagem_regras
A1: exercicio_id | B1: nome | C1: n_alternativas | D1: n_sem_equipamento | E1: status | G1: Resumo
A2: 1 | B2: =IFERROR(INDEX(exercicio!$B$2:$B$190,MATCH(A2,exercicio!$A$2:$A$190,0)),"") -> Supino Reto com Barra | C2: =COUNTIF(exercicio_alternativo!$A$2:$A$400,A2) -> 4 | D2: =SUMPRODUCT((exercicio_alternativo!$A$2:$A$400=A2)*(exercicio_alternativo!$G$2:$G$400=TRUE())) -> 1 | E2: =IF(AND(C2>=2,C2<=4,D2>=1),"OK",IF(AND(C2>=2,C2<=4),"FALTA ALTERNATIVA SEM EQUIPAMENTO","FORA DE 2 A 4 ALTERNATIVAS")) -> OK | G2: Exercícios OK: | H2: =COUNTIF(E2:E90,"OK") -> 88
A3: 2 | B3: =IFERROR(INDEX(exercicio!$B$2:$B$190,MATCH(A3,exercicio!$A$2:$A$190,0)),"") -> Supino Inclinado com Halteres | C3: =COUNTIF(exercicio_alternativo!$A$2:$A$400,A3) -> 4 | D3: =SUMPRODUCT((exercicio_alternativo!$A$2:$A$400=A3)*(exercicio_alternativo!$G$2:$G$400=TRUE())) -> 1 | E3: =IF(AND(C3>=2,C3<=4,D3>=1),"OK",IF(AND(C3>=2,C3<=4),"FALTA ALTERNATIVA SEM EQUIPAMENTO","FORA DE 2 A 4 ALTERNATIVAS")) -> OK | G3: Total: | H3: =COUNTA(A2:A90) -> 89
A4: 3 | B4: =IFERROR(INDEX(exercicio!$B$2:$B$190,MATCH(A4,exercicio!$A$2:$A$190,0)),"") -> Voador Peitoral | C4: =COUNTIF(exercicio_alternativo!$A$2:$A$400,A4) -> 3 | D4: =SUMPRODUCT((exercicio_alternativo!$A$2:$A$400=A4)*(exercicio_alternativo!$G$2:$G$400=TRUE())) -> 1 | E4: =IF(AND(C4>=2,C4<=4,D4>=1),"OK",IF(AND(C4>=2,C4<=4),"FALTA ALTERNATIVA SEM EQUIPAMENTO","FORA DE 2 A 4 ALTERNATIVAS")) -> OK
A5: 4 | B5: =IFERROR(INDEX(exercicio!$B$2:$B$190,MATCH(A5,exercicio!$A$2:$A$190,0)),"") -> Flexão de Braço | C5: =COUNTIF(exercicio_alternativo!$A$2:$A$400,A5) -> 4 | D5: =SUMPRODUCT((exercicio_alternativo!$A$2:$A$400=A5)*(exercicio_alternativo!$G$2:$G$400=TRUE())) -> 2 | E5: =IF(AND(C5>=2,C5<=4,D5>=1),"OK",IF(AND(C5>=2,C5<=4),"FALTA ALTERNATIVA SEM EQUIPAMENTO","FORA DE 2 A 4 ALTERNATIVAS")) -> OK
A6: 5 | B6: =IFERROR(INDEX(exercicio!$B$2:$B$190,MATCH(A6,exercicio!$A$2:$A$190,0)),"") -> Flexão com Apoio Afastado | C6: =COUNTIF(exercicio_alternativo!$A$2:$A$400,A6) -> 4 | D6: =SUMPRODUCT((exercicio_alternativo!$A$2:$A$400=A6)*(exercicio_alternativo!$G$2:$G$400=TRUE())) -> 2 | E6: =IF(AND(C6>=2,C6<=4,D6>=1),"OK",IF(AND(C6>=2,C6<=4),"FALTA ALTERNATIVA SEM EQUIPAMENTO","FORA DE 2 A 4 ALTERNATIVAS")) -> OK
A7: 6 | B7: =IFERROR(INDEX(exercicio!$B$2:$B$190,MATCH(A7,exercicio!$A$2:$A$190,0)),"") -> Flexão com Pés Elevados | C7: =COUNTIF(exercicio_alternativo!$A$2:$A$400,A7) -> 4 | D7: =SUMPRODUCT((exercicio_alternativo!$A$2:$A$400=A7)*(exercicio_alternativo!$G$2:$G$400=TRUE())) -> 2 | E7: =IF(AND(C7>=2,C7<=4,D7>=1),"OK",IF(AND(C7>=2,C7<=4),"FALTA ALTERNATIVA SEM EQUIPAMENTO","FORA DE 2 A 4 ALTERNATIVAS")) -> OK
A8: 7 | B8: =IFERROR(INDEX(exercicio!$B$2:$B$190,MATCH(A8,exercicio!$A$2:$A$190,0)),"") -> Mergulho em Paralelas | C8: =COUNTIF(exercicio_alternativo!$A$2:$A$400,A8) -> 3 | D8: =SUMPRODUCT((exercicio_alternativo!$A$2:$A$400=A8)*(exercicio_alternativo!$G$2:$G$400=TRUE())) -> 2 | E8: =IF(AND(C8>=2,C8<=4,D8>=1),"OK",IF(AND(C8>=2,C8<=4),"FALTA ALTERNATIVA SEM EQUIPAMENTO","FORA DE 2 A 4 ALTERNATIVAS")) -> OK
A9: 8 | B9: =IFERROR(INDEX(exercicio!$B$2:$B$190,MATCH(A9,exercicio!$A$2:$A$190,0)),"") -> Flexão Diamante | C9: =COUNTIF(exercicio_alternativo!$A$2:$A$400,A9) -> 4 | D9: =SUMPRODUCT((exercicio_alternativo!$A$2:$A$400=A9)*(exercicio_alternativo!$G$2:$G$400=TRUE())) -> 2 | E9: =IF(AND(C9>=2,C9<=4,D9>=1),"OK",IF(AND(C9>=2,C9<=4),"FALTA ALTERNATIVA SEM EQUIPAMENTO","FORA DE 2 A 4 ALTERNATIVAS")) -> OK
A10: 9 | B10: =IFERROR(INDEX(exercicio!$B$2:$B$190,MATCH(A10,exercicio!$A$2:$A$190,0)),"") -> Flexão em Pique | C10: =COUNTIF(exercicio_alternativo!$A$2:$A$400,A10) -> 4 | D10: =SUMPRODUCT((exercicio_alternativo!$A$2:$A$400=A10)*(exercicio_alternativo!$G$2:$G$400=TRUE())) -> 2 | E10: =IF(AND(C10>=2,C10<=4,D10>=1),"OK",IF(AND(C10>=2,C10<=4),"FALTA ALTERNATIVA SEM EQUIPAMENTO","FORA DE 2 A 4 ALTERNATIVAS")) -> OK
A11: 10 | B11: =IFERROR(INDEX(exercicio!$B$2:$B$190,MATCH(A11,exercicio!$A$2:$A$190,0)),"") -> Flexão nas Pontas dos Dedos | C11: =COUNTIF(exercicio_alternativo!$A$2:$A$400,A11) -> 3 | D11: =SUMPRODUCT((exercicio_alternativo!$A$2:$A$400=A11)*(exercicio_alternativo!$G$2:$G$400=TRUE())) -> 1 | E11: =IF(AND(C11>=2,C11<=4,D11>=1),"OK",IF(AND(C11>=2,C11<=4),"FALTA ALTERNATIVA SEM EQUIPAMENTO","FORA DE 2 A 4 ALTERNATIVAS")) -> OK
A12: 11 | B12: =IFERROR(INDEX(exercicio!$B$2:$B$190,MATCH(A12,exercicio!$A$2:$A$190,0)),"") -> Desenvolvimento com Halteres | C12: =COUNTIF(exercicio_alternativo!$A$2:$A$400,A12) -> 3 | D12: =SUMPRODUCT((exercicio_alternativo!$A$2:$A$400=A12)*(exercicio_alternativo!$G$2:$G$400=TRUE())) -> 1 | E12: =IF(AND(C12>=2,C12<=4,D12>=1),"OK",IF(AND(C12>=2,C12<=4),"FALTA ALTERNATIVA SEM EQUIPAMENTO","FORA DE 2 A 4 ALTERNATIVAS")) -> OK
